Workbook

Sheet 📋 使い方
B2: ヨミテ マーケティング スキル評価シート
B3: あなたの「今」を正直に。成長の地図を描こう。
B5: ▌ 評価基準
B6: ◎ | C6: 完全にできる — 高水準で自走できる。成果を出している実績がある
B7: ○ | C7: おおむねできる — ほぼ自走できる。一部確認・サポートがあれば対応可能
B8: △ | C8: 理解しているが不十分 — 概念は理解しているが実践が足りない。成果に繋がっていない
B9: × | C9: 現状できない — 未経験または知識が不十分。習得・強化が必要
B11: ▌ 使い方
B12: STEP 1 | C12: スキル評価シートを開く ／ 「📊 スキル評価シート」タブをクリック
B13: STEP 2 | C13: 自己評価を記入する ／ 「自己評価」列に ◎ / ○ / △ / × のいずれかを入力（プルダウンから選択可）
B14: STEP 3 | C14: 上長にレビューしてもらう ／ 「上長評価」列を上長が記入。自己評価とのズレを1on1で確認
B15: STEP 4 | C15: 集計シートで振り返る ／ 「📈 集計」タブで得点とカテゴリー別スコアを確認
B17: ▌ ひとことアドバイス
B18: 💬 | C18: 自己評価は「できてるはず」ではなく「成果を出した実績がある」で◎をつけよう。
B19: 💬 | C19: △や×は「これから伸びる余地」。正直に書くほど、次のアクションが明確になる。
B20: 💬 | C20: 「◎を多くつけること」が目的ではない。自分と上長の見え方のズレを発見することが目的。

Sheet 📊 スキル評価シート
A2: ヨミテ マーケティング スキル評価シート | Web広告領域 特化版
A3: # | B3: No. | C3: スキル名 | D3: ◎ のレベル（この水準で◎） | E3: 重要度 | F3: 自己評価 | G3: 上長評価 | H3: メモ・コメント
A4: 💡 コピー力・法規制活用・訴求開発力
A5: 0 | B5: 0-1 | C5: ★ 訴求の手数 | D5: 1テーマに対して30パターン以上の訴求軸（悩み/比較/権威/感情/数字…）を量産できる。同じ表現を繰り返さず「まだ試していない角度」を常に問い続けられる | E5: CPA直結
A6: 0 | B6: 0-2 | C6: ★ 言葉の選択と精度 | D6: 「効果的」ではなく「3週間後の朝に鏡で驚く」——抽象を具体的な生活シーンに変換できる。「この言葉でなければならない理由」を語れる | E6: CPA直結
A7: 0 | B7: 0-3 | C7: ⚖ 法規制を活用した強い訴求設計 | D7: 薬機法・景表法・特商法の規制範囲を正確に理解した上で「アウトではなくギリギリセーフの最大表現」を設計できる。規制を武器にして強い訴求を作れる | E7: CPA直結
A8: 0 | B8: 0-4 | C8: ⚖ 法律×コピーの即時判断 | D8: 作ったコピーを見て「アウト/グレー/セーフ」を即座に分類できる。「なんとなく怖い」ではなく「ここまでは出せる」の根拠を持って動ける | E8: CPA直結
A9: 0 | B9: 0-5 | C9: ★ エビデンスを取りに行く姿勢 | D9: 「こういうコピーにしたいからこのエビデンスが必要」と逆算して動ける。外部アンケート委託・クラウドワークス活用・成分データ調査まで自分で動ける | E9: CPA直結
A10: 0 | B10: 0-6 | C10: インタビュー発言のコピー化 | D10: 顧客インタビューで出た言葉を「そのまま使えるコピー候補」として聞き取れる。インタビュー翌週に制作物に反映できている | E10: CPA直結
A12: 📊 広告運用
A13: 1 | B13: 1-1 | C13: 媒体ロジック理解 | D13: Meta/Google/TikTok/LINE/Yahoo等の配信ロジックを説明できる。媒体ごとの得意不得意を商品特性と紐づけて判断できる | E13: CPA直結
A14: 1 | B14: 1-2 | C14: アカウント設定・構造設計 | D14: キャンペーン/広告セット/広告のレイヤー設計。テスト用・スケール用・リターゲ用の構造設計。新媒体への初期設定が一人でできる | E14: 基盤
A15: 1 | B15: 1-3 | C15: タグ設置・計測連携 | D15: Metaピクセル/GA4/GTM設置・確認。EC-Forceとの連携。「今の計測は正確か」を常に疑える。計測漏れによるCPA誤認を起こさない | E15: CPA直結
A16: 1 | B16: 1-4 | C16: 予算コントロール（伸縮判断） | D16: CPAが安い時に素早く伸ばし、高騰時に適切に抑える判断力。「今日の数字」を見て午前中に動ける。Day100件を軸にした日次判断基準を持っている | E16: CPA直結
A17: 1 | B17: 1-5 | C17: オーディエンス設計 | D17: Meta類似/インタレスト/リターゲの組み合わせ設計。Advantage+活用の判断。テスト→スケールへの切り替え判断 | E17: CPA直結
A18: 1 | B18: 1-6 | C18: 広告審査・リジェクト対応 | D18: 健康食品・スキンケア領域の各媒体ポリシー理解。リジェクト時に「どこを変えれば通るか」を即判断できる | E18: CVR
A19: 1 | B19: 1-7 | C19: クリエイティブ疲弊検知・入れ替え | D19: CTR/CPAの推移から疲弊を検知する数値基準を持っている。「次に何を入れるか」の方向性判断までセット。疲弊前に次を用意できる先回り力 | E19: CPA直結
A20: 1 | B20: 1-8 | C20: リターゲ施策設計 | D20: ロジカド・SMSリマーケ・商標リスティング等の活用。CVに至らなかったユーザーへの再アプローチ設計。SMS文言の最適化も含む | E20: CVR
A22: 📝 記事LP
A23: 2 | B23: 2-1 | C23: ★ コンテンツ戦略設計 | D23: 「何を言うべきか」の上流設計。競合との比較でギャップを特定し「何を作れば勝てるか」を考え抜ける。不足素材を自ら動いて埋める姿勢がある | E23: CPA直結
A24: 2 | B24: 2-2 | C24: 記事LP全体構成設計 | D24: フック→共感→問題→新認識→解決策→証拠→オファー→CTAの全体ワイヤー設計。訴求軸の選定・情報の順番・各ブロックの長さ配分まで設計できる | E24: CPA直結
A25: 2 | B25: 2-3 | C25: 権威性の調達・創出 | D25: 権威性が弱い時に「作りに行く」。外部アンケート委託・クラウドワークスでのレポート収集・質の高い口コミのための人探しまで動ける | E25: CPA直結
A26: 2 | B26: 2-4 | C26: フック設計（冒頭200字） | D26: 「これ私のことだ」と思わせる冒頭の言語設計。ターゲットの悩みを当人より解像度高く言語化できる。読み飛ばしを許さない引力がある | E26: CPA直結
A27: 2 | B27: 2-5 | C27: ★ 構成内の具体的表現力 | D27: 「腸内環境が乱れる」→「毎朝お腹が張って、出かける前に不安になる」。抽象を具体的な生活シーンに変換できる。読んでいて映像が浮かぶ描写 | E27: CPA直結
A28: 2 | B28: 2-6 | C28: 感情アーク・全文ライティング | D28: 読者の感情温度を「共感の谷→希望の山→決断」と設計するアーク構成力。全文を一人で書き切れる | E28: CPA直結
A29: 2 | B29: 2-7 | C29: スマホUI・離脱防止設計 | D29: スマホで見た時の読者体験を常に想像して制作できる。見出し・ウィジェット・キャッチーなワード選定で「縦スクロールで離脱されない」仕掛けを意図的に設計できる | E29: CPA直結
A30: 2 | B30: 2-8 | C30: 記事LP内画像・ビジュアル設計 | D30: 記事LP内の画像（グラフ・Before-After・表）をスマホ表示前提で設計できる。「この画像でCVRが上がるか」を問える | E30: CVR
A31: 2 | B31: 2-9 | C31: 信頼構造設計 | D31: 監修者・成分エビデンス・口コミ・数字の配置設計。「いつ・どこで信頼を作るか」の構造判断。早期権威配置の効果を理解している | E31: CVR
A32: 2 | B32: 2-10 | C32: CTA設計（数・配置・文言） | D32: CTAの本数・配置・ボタン文言・前後誘導文の設計。「今申し込まないと損だと感じさせる」必然性のあるCTA設計 | E32: CPA直結
A33: 2 | B33: 2-11 | C33: ⚖ 薬機法・景表法の表現設計 | D33: 各商品の表現規制を把握。「アウト/グレー/セーフ」を即判断し、CVRを下げずにリスクゼロを保てる。規制ギリギリの最大訴求を複数提示できる | E33: CVR
A34: 2 | B34: 2-12 | C34: 記事LP PDCA | D34: フック/構成/CTA/オファー表現のABテスト設計と結果判断。ヒートマップ・スクロール到達率でのボトルネック特定と改善サイクルを週次で回せる | E34: CPA直結
A36: 🛒 商品LP・チャットボット
A37: 3 | B37: 3-1 | C37: 商品LP全体構成・コピー設計 | D37: FV→特徴訴求→成分→使い方→口コミ→FAQ→CTAの各セクション設計。FVキャッチを単独で書けてデザイナーブリーフに落とせる | E37: CPA直結
A38: 3 | B38: 3-2 | C38: チャットボットシナリオ設計 | D38: 分岐フロー設計・各分岐の文言・離脱防止ライン設計。申込前の最後の疑問を潰すシナリオ構成。初回価格/特典/緊急性の見せ方設計 | E38: CPA直結
A39: 3 | B39: 3-3 | C39: オファー・価格設計 | D39: 初回価格・割引率・特典のセット設計。申込衝動を引き出す価格と継続率を下げない特典設計。キャンペーン設計でCVRをブーストできる | E39: CPA直結
A40: 3 | B40: 3-4 | C40: EC-Force仕様理解・LP高速化 | D40: EC-Forceの申込フォーム・定期設定の理解。jQuery禁忌を把握。画像最適化/preload/fetchpriorityによる高速化の技術判断 | E40: CVR
A41: 3 | B41: 3-5 | C41: デザイナー・コーダーブリーフ | D41: ターゲット感情/色温度/情報優先度/視線誘導まで言語化したブリーフ。初稿から8割合格品質を引き出す指示精度 | E41: 基盤
A42: 3 | B42: 3-6 | C42: 商品LP・CB PDCA | D42: FV/CTA/オファー表現/チャットボット分岐のABテスト設計と結果判断。「何を変えたらどれだけ動いたか」を定量で語れる | E42: CPA直結
A44: 🎬 動画クリエイティブ
A45: 4 | B45: 4-1 | C45: 動画企画・訴求軸設計 | D45: UGC/解説/Before-After/比較/証言等の「型」選定と最適型適用。メタの勝ちクリエイティブのTikTok転用判断 | E45: CPA直結
...

Sheet 📈 集計
B2: スキル評価 集計結果
B4: カテゴリー | C4: ◎ | D4: ○ | E4: △ | F4: ×
B5: 💡 コピー力・法規制活用・訴求開発力 | C5: =COUNTIF('📊 スキル評価シート'!$F$5:$F$10,"◎") | D5: =COUNTIF('📊 スキル評価シート'!$F$5:$F$10,"○") | E5: =COUNTIF('📊 スキル評価シート'!$F$5:$F$10,"△") | F5: =COUNTIF('📊 スキル評価シート'!$F$5:$F$10,"×")
B6: 📊 広告運用 | C6: =COUNTIF('📊 スキル評価シート'!$F$13:$F$20,"◎") | D6: =COUNTIF('📊 スキル評価シート'!$F$13:$F$20,"○") | E6: =COUNTIF('📊 スキル評価シート'!$F$13:$F$20,"△") | F6: =COUNTIF('📊 スキル評価シート'!$F$13:$F$20,"×")
B7: 📝 記事LP | C7: =COUNTIF('📊 スキル評価シート'!$F$23:$F$34,"◎") | D7: =COUNTIF('📊 スキル評価シート'!$F$23:$F$34,"○") | E7: =COUNTIF('📊 スキル評価シート'!$F$23:$F$34,"△") | F7: =COUNTIF('📊 スキル評価シート'!$F$23:$F$34,"×")
B8: 🛒 商品LP・チャットボット | C8: =COUNTIF('📊 スキル評価シート'!$F$37:$F$42,"◎") | D8: =COUNTIF('📊 スキル評価シート'!$F$37:$F$42,"○") | E8: =COUNTIF('📊 スキル評価シート'!$F$37:$F$42,"△") | F8: =COUNTIF('📊 スキル評価シート'!$F$37:$F$42,"×")
B9: 🎬 動画クリエイティブ | C9: =COUNTIF('📊 スキル評価シート'!$F$45:$F$52,"◎") | D9: =COUNTIF('📊 スキル評価シート'!$F$45:$F$52,"○") | E9: =COUNTIF('📊 スキル評価シート'!$F$45:$F$52,"△") | F9: =COUNTIF('📊 スキル評価シート'!$F$45:$F$52,"×")
B10: 🖼️ 静止画クリエイティブ | C10: =COUNTIF('📊 スキル評価シート'!$F$55:$F$59,"◎") | D10: =COUNTIF('📊 スキル評価シート'!$F$55:$F$59,"○") | E10: =COUNTIF('📊 スキル評価シート'!$F$55:$F$59,"△") | F10: =COUNTIF('📊 スキル評価シート'!$F$55:$F$59,"×")
B11: 🎥 撮影・制作ディレクション | C11: =COUNTIF('📊 スキル評価シート'!$F$62:$F$67,"◎") | D11: =COUNTIF('📊 スキル評価シート'!$F$62:$F$67,"○") | E11: =COUNTIF('📊 スキル評価シート'!$F$62:$F$67,"△") | F11: =COUNTIF('📊 スキル評価シート'!$F$62:$F$67,"×")
B12: 🎤 顧客インタビュー・インサイト抽出 | C12: =COUNTIF('📊 スキル評価シート'!$F$70:$F$74,"◎") | D12: =COUNTIF('📊 スキル評価シート'!$F$70:$F$74,"○") | E12: =COUNTIF('📊 スキル評価シート'!$F$70:$F$74,"△") | F12: =COUNTIF('📊 スキル評価シート'!$F$70:$F$74,"×")
B13: 🔭 競合分析・市場調査 | C13: =COUNTIF('📊 スキル評価シート'!$F$77:$F$81,"◎") | D13: =COUNTIF('📊 スキル評価シート'!$F$77:$F$81,"○") | E13: =COUNTIF('📊 スキル評価シート'!$F$77:$F$81,"△") | F13: =COUNTIF('📊 スキル評価シート'!$F$77:$F$81,"×")
B14: 合計 | C14: =SUM(C5:C13) | D14: =SUM(D5:D13) | E14: =SUM(E5:E13) | F14: =SUM(F5:F13)
B16: ※ 上の集計は「自己評価」列のみをカウントしています。上長評価の集計は別途ご確認ください。
